Workbook
Name Asignaturas2: [1]ASIGNATURAS!$D$2:$D$55
Name Asignaturas2: ASIGNATURAS!$D$2:$D$55
Name AULAS: [1]Aulas!$A$2:$A$172
Name AULAS: Aulas!$A$2:$A$198
Name Aulas_C: Aulas!$A$75:$A$90
Name CAGIE__1: ASIGNATURAS!$F$269:$F$273
Name CAGIE__2: ASIGNATURAS!$F$274:$F$275
Name CAGIE_1: ASIGNATURAS!$H$269:$H$273
Name CAGIE_2: ASIGNATURAS!$H$274:$H$275
Name CAGII__1: ASIGNATURAS!$F$278:$F$286
Name CAGII__2: ASIGNATURAS!$F$291:$F$311
Name CAGII_1: ASIGNATURAS!$H$278:$H$286
Name CAGII_2: ASIGNATURAS!$H$291:$H$311
Name CAGIM__1: ASIGNATURAS!$F$260:$F$264
Name CAGIM__2: ASIGNATURAS!$F$265:$F$266
Name CAGIM_1: ASIGNATURAS!$H$260:$H$264
Name CAGIM_2: ASIGNATURAS!$H$265:$H$266
Name dg_3: ASIGNATURAS!$I$314:$I$319
Name dg_4: ASIGNATURAS!$J$314:$J$318
Name DGME: ASIGNATURAS!$F$313:$F$322
Name DGME_1: [1]ASIGNATURAS!$G$281:$G$289
Name DGME_1: ASIGNATURAS!$G$314:$G$322
Name DGME_10: ASIGNATURAS!$P$314:$P$322
Name DGME_2: [1]ASIGNATURAS!$H$281:$H$289
Name DGME_2: ASIGNATURAS!$H$314:$H$322
Name DGME_3: ASIGNATURAS!$I$314:$I$322
Name DGME_4: ASIGNATURAS!$J$314:$J$322
Name DGME_5: ASIGNATURAS!$K$314:$K$322
Name DGME_6: ASIGNATURAS!$L$314:$L$322
Name DGME_7: ASIGNATURAS!$M$315:$M$323
Name DGME_8: ASIGNATURAS!$N$314:$N$322
Name DGME_9: ASIGNATURAS!$O$314:$O$322
Name e: [1]Aulas!$G$2:$G$4
Name e: Aulas!$G$2:$G$4
Name GIE: ASIGNATURAS!$A$11:$A$18
Name GIE__1: ASIGNATURAS!$F$46:$F$51
Name GIE__2: ASIGNATURAS!$F$52:$F$57
Name GIE__3: ASIGNATURAS!$F$58:$F$62
Name GIE__4: ASIGNATURAS!$F$63:$F$67
Name GIE__5: ASIGNATURAS!$F$68:$F$72
Name GIE__6: ASIGNATURAS!$F$73:$F$77
Name GIE__7: ASIGNATURAS!$F$78:$F$86
Name GIE__8: ASIGNATURAS!$F$87:$F$88
Name GIE_1: ASIGNATURAS!$H$46:$H$51
Name GIE_2: ASIGNATURAS!$H$52:$H$57
Name GIE_3: ASIGNATURAS!$H$58:$H$62
Name GIE_4: ASIGNATURAS!$H$63:$H$67
Name GIE_5: ASIGNATURAS!$H$68:$H$72
Name GIE_6: ASIGNATURAS!$H$73:$H$77
Name GIE_7: [1]ASIGNATURAS!$H$78:$H$86
Name GIE_7: ASIGNATURAS!$H$78:$H$86
Name GIE_8: ASIGNATURAS!$H$87:$H$88
Name GII: ASIGNATURAS!$A$29:$A$36
Name GII__1: ASIGNATURAS!$F$152:$F$156
Name GII__2: ASIGNATURAS!$F$157:$F$161
Name GII__3: ASIGNATURAS!$F$162:$F$166
Name GII__4: ASIGNATURAS!$F$167:$F$171
Name GII__5: ASIGNATURAS!$F$172:$F$176
Name GII__6: [1]ASIGNATURAS!$F$170:$F$174
Name GII__6: ASIGNATURAS!$F$177:$F$181

Sheet GIEIA
A1: =VLOOKUP(A4,ASIGNATURAS!$A$2:$D$151, 3, FALSE) -> 1º Grado en Ingeniería Electrónica Industrial y Automática | Z1: =Aulas!G5 -> Curso 2024-2025
A2: =VLOOKUP(A4,ASIGNATURAS!$A$2:$D$151, 2, FALSE) -> Semestre temporal: 1º (1º Semestre Académico) | Z2: Aula 35-A2
A3: Grupo: MANAÑA
A4: GIE_1
A5: Hora | B5: LUNES | H5: MARTES | N5: MIÉRCOLES | T5: JUEVES | Z5: VIERNES
A6: 08:30 - 09:30 | B6: INFORMATICA | H6: CÁLCULO | N6: EXP. GRAF. | T6: CALCULO | Z6: FISICA I
B7: Aula 35-A2 | H7: Aula 35-A2 | N7: Aula 41-A2 | T7: Aula 35-A2 | Z7: Aula 35-A2
A8: 09:30 - 10:30 | B8: FÍSICA I | H8: ALGEBRA | N8: (101) | O8: Aula 53-A2 (CAD) | P8: (102) | Q8: Aula 41-A2 | T8: ALGEBRA | Z8: INFORMATICA
B9: Aula 35-A2 | H9: Aula 35-A2 | N9: EXPRESION GRAFICA | P9: EXPRESION GRAFICA | T9: Aula 35-A2 | Z9: Aula 35-A2
A10: 10:30 - 11:30 | B10: (101) | C10: Lab. Fisica / Aula 42-A2 | D10: (102) | E10: Aula Inf. 1B | H10: (101) | I10: Aula 35-A2 / Aula 52-A2 | J10: (102) | K10: Lab 46-A1 | T10: (102) | U10: Aula 35-A2 / Aula 52-A2 | Z10: (101) | AA10: Lab 46-A1 | AB10: (102) | AC10: Lab. Fisica / Aula 42-A2
B11: FÍSICA I | D11: CALCULO | H11: ALGEBRA | J11: INFORMÁTICA | T11: ALGEBRA | Z11: INFORMATICA | AB11: FISICA I
A12: 11:30 - 12:30
A14: 12:30 - 13:30 | B14: (101) | C14: Aula Inf. 1B
B15: CALCULO
A16: 13:30 - 14:30
A19: Nombre abreviado | C19: Nombre completo | M19: GIE__1 | O19: ECTS | Q19: Profesor / es
A20: =VLOOKUP(M20,ASIGNATURAS!$F$1:$L$1022, 3, FALSE) -> ÁLGEBRA | C20: =VLOOKUP(M20,ASIGNATURAS!$F$1:$L$1022, 4, FALSE) -> Álgebra y Ecuaciones Diferenciales | M20: 6392 | O20: =VLOOKUP(M20,ASIGNATURAS!$F$1:$L$1022, 5, FALSE) -> 6 | Q20: =VLOOKUP(M20,ASIGNATURAS!$F$1:$L$1022, 6, FALSE) -> Roberto Casado
A21: =VLOOKUP(M21,ASIGNATURAS!$F$1:$L$1022, 3, FALSE) -> CÁLCULO | C21: =VLOOKUP(M21,ASIGNATURAS!$F$1:$L$1022, 4, FALSE) -> Cálculo | M21: 6393 | O21: =VLOOKUP(M21,ASIGNATURAS!$F$1:$L$1022, 5, FALSE) -> 6 | Q21: =VLOOKUP(M21,ASIGNATURAS!$F$1:$L$1022, 6, FALSE) -> Roberto Casado
A22: =VLOOKUP(M22,ASIGNATURAS!$F$1:$L$1022, 3, FALSE) -> FÍSICA I | C22: =VLOOKUP(M22,ASIGNATURAS!$F$1:$L$1022, 4, FALSE) -> Física I | M22: 6394 | O22: =VLOOKUP(M22,ASIGNATURAS!$F$1:$L$1022, 5, FALSE) -> 6 | Q22: =VLOOKUP(M22,ASIGNATURAS!$F$1:$L$1022, 6, FALSE) -> Alfonso Blasco Sanz
A23: =VLOOKUP(M23,ASIGNATURAS!$F$1:$L$1022, 3, FALSE) -> EXP. GRÁFICA | C23: =VLOOKUP(M23,ASIGNATURAS!$F$1:$L$1022, 4, FALSE) -> Expresión Gráfica | M23: 6395 | O23: =VLOOKUP(M23,ASIGNATURAS!$F$1:$L$1022, 5, FALSE) -> 6 | Q23: =VLOOKUP(M23,ASIGNATURAS!$F$1:$L$1022, 6, FALSE) -> Esteban García Maté, Esther Baños García
A24: =VLOOKUP(M24,ASIGNATURAS!$F$1:$L$1022, 3, FALSE) -> INFORMÁTICA | C24: =VLOOKUP(M24,ASIGNATURAS!$F$1:$L$1022, 4, FALSE) -> Informática Básica | M24: 6396 | O24: =VLOOKUP(M24,ASIGNATURAS!$F$1:$L$1022, 5, FALSE) -> 6 | Q24: =VLOOKUP(M24,ASIGNATURAS!$F$1:$L$1022, 6, FALSE) -> Beatriz Gil Arroyo, Sergio Martín Marquina
A27: GRUPOS TEÓRICOS = 1
A28: GRUPOS PRÁCTICOS = 2
A30: Nota: Estos horarios podrán ser modificados por necesidades docentes (desdoble de grupos, ocupación de laboratorios, contratación de profesorado…)
A33: =VLOOKUP(A36,ASIGNATURAS!$A$2:$D$151, 3, FALSE) -> 1º Grado en Ingeniería Electrónica Industrial y Automática | Z33: =Z1 -> Curso 2024-2025
A34: =VLOOKUP(A36,ASIGNATURAS!$A$2:$D$151, 2, FALSE) -> Semestre temporal: 2º (2º Semestre Académico) | Z34: Aula 34-A2
A35: Grupo: MANAÑA
A36: GIE_2
A37: Hora | B37: LUNES | H37: MARTES | N37: MIÉRCOLES | T37: JUEVES | Z37: VIERNES
A38: 08:30 - 09:30 | B38: QUIMICA | H38: QUIMICA | N38: ECONOMIA | T38: FISICA II | Z38: AMP. CALCULO
B39: Aula 34-A2 | H39: Aula 34-A2 | N39: Aula 21-A1 | T39: Aula 34-A2 | Z39: Aula 34-A2
A40: 09:30 - 10:30 | B40: MATERIALES | H40: MATERIALES | N40: ECONOMIA | T40: AMP. CALCULO | Z40: FISICA II
B41: Aula 34-A2 | H41: Aula 34-A2 | N41: Aula 21-A1 | T41: Aula 34-A2 | Z41: Aula 34-A2
A42: 10:30 - 11:30 | D42: (102) | E42: Aula 21-A1 | H42: (101) | I42: Aula 21-A1 | J42: (102) | K42: Lab. Materiales | N42: (101) | O42: Lab. Materiales | P42: (102) | Q42: Aula 52-A2 (Inf.)/36-A2 | V42: (102) | W42: Lab. Fisica / Aula 44-A2 | Z42: (101) | AA42: Lab. Fisica / Aula 44-A2
D43: ECONOMIA | H43: ECONOMIA | J43: MATERIALES | N43: MATERIALES | P43: AMP. CALCULO | V43: FISICA II | Z43: FISICA II
A44: 11:30 - 12:30
A46: 12:30 - 13:30 | N46: (101) | O46: Lab. Química / Aula 44-A2 | V46: (102) | W46: Lab. Química / Aula 44-A2 | Z46: (101) | AA46: Aula 52-A2 (Inf.)/36-A2
N47: QUIMICA | V47: QUIMICA | Z47: AMP. CALCULO
A48: 13:30 - 14:30
A51: Nombre abreviado | C51: Nombre completo | M51: GIE__2 | O51: ECTS | Q51: Profesor / es
...

Sheet GIM
A1: =VLOOKUP(A4,ASIGNATURAS!$A$2:$D$151, 3, FALSE) -> 1º Grado en Ingeniería Mecánica | AP1: =Aulas!G5 -> Curso 2024-2025
A2: =VLOOKUP(A4,ASIGNATURAS!$A$2:$D$151, 2, FALSE) -> Semestre temporal: 1º (1º Semestre Académico) | AP2: Aula 51-A1
A3: Grupo: MANAÑA
A4: GIM_1
A5: Hora | B5: LUNES | L5: MARTES | V5: MIÉRCOLES | AF5: JUEVES | AP5: VIERNES
A6: 08:30 - 09:30 | B6: (101) | C6: Aula 53-A2 (CAD) / 41-A2 (Tab) | F6: (103) | G6: Aula 55-A2 (CAD) / 41-A2 (Tab) | P6: (103) | Q6: Lab. Fisica / Aula -31A2 | R6: (104) | S6: Lab. Química | T6: (105) | U6: Aula 51-A2 (Inf.) | V6: (101) | W6: Lab. Fisica / Aula 31-A2 | X6: (102) | Y6: Aula 34-A2 / Aula 52-A2 | AF6: (101) | AG6: Aula 51-A2 (Inf.) | AH6: (102) | AI6: Lab. Fisica / Aula 34-A2 | AJ6: (103) | AK6: Lab. Química | AV6: (104) | AW6: Lab. Fisica / Aula -31A2
B7: EXP. GRAFICA I | F7: EXP. GRAFICA I | P7: FISICA I | R7: QUIMICA | T7: CALCULO | V7: FISICA I | X7: ALGEBRA | AF7: CALCULO | AH7: FISICA I | AJ7: QUIMICA | AV7: FISICA I
A8: 09:30 - 10:30 | D8: (102) | E8: Lab. Química | H8: (104) | I8: Aula 34-A2 / Aula 52-A2
D9: QUIMICA | H9: ALGEBRA
A10: 10:30 - 11:30 | L10: CALCULO | R10: Aula 51-A1 | V10: ALGEBRA | AB10: Aula 51-A1 | AF10: CALCULO | AL10: Aula 51-A1 | AP10: QUIMICA | AV10: Aula 51-A1
A12: 11:30 - 12:30 | B12: (101) | C12: Lab. Química | D12: (102) | E12: Aula 53-A2 (CAD) / 41-A2 (Tab) | F12: (103) | G12: Aula 34-A2 / Aula 52-A2 | H12: (104) | I12: Aula 55-A2 (CAD) / 41-A2 (Tab) | L12: FISICA I | R12: Aula 51-A1 | V12: FISICA I | AB12: Aula 51-A1 | AF12: QUIMICA | AL12: Aula 51-A1 | AP12: ALGEBRA | AV12: Aula 51-A1
B13: QUIMICA | D13: EXP. GRAFICA I | F13: ALGEBRA | H13: EXP. GRAFICA I
A14: 12:30 - 13:30 | L14: EXP. GRAFICA I | R14: Aula 51-A1 | AD14: (105) | AE14: Lab. Fisica / Aula 31-A2
AD15: FISICA I
A16: 13:30 - 14:30
A18: Hora | B18: LUNES | L18: MARTES | V18: MIÉRCOLES | AF18: JUEVES | AP18: VIERNES
A19: 15:30 - 16:30 | T19: (105) | U19: Aula 52-A2 (Inf.) | V19: (101) | W19: Aula 52-A2 (Inf.) / 32-A2 | AL19: (104) | AM19: Aula 52-A2 (Inf.)
T20: ALGEBRA | V20: ALGEBRA | AL20: CALCULO
A21: 16:30 - 17:30 | D21: (102) | E21: Aula 52-A2 (Inf.)
D22: CALCULO
A23: 17:30 - 18:30 | Z23: (103) | AA23: Aula 52-A2 (Inf.)
Z24: CALCULO
A25: 18:30 - 19:30
A27: Nombre abreviado | C27: Nombre completo | O27: GIM__1 | S27: ECTS | U27: Profesor / es | AQ27: GRUPO TEÓRICO (1)
A28: =VLOOKUP(O28,[2]ASIGNATURAS!$F$1:$L$1022, 3, FALSE) -> CÁLCULO | C28: =VLOOKUP(O28,[2]ASIGNATURAS!$F$1:$L$1022, 4, FALSE) -> Cálculo | O28: 6302 | S28: =VLOOKUP(O28,[2]ASIGNATURAS!$F$1:$L$1022, 5, FALSE) -> 6 | U28: =VLOOKUP(O28,[2]ASIGNATURAS!$F$1:$L$1022, 6, FALSE) -> Ana García
A29: =VLOOKUP(O29,[2]ASIGNATURAS!$F$1:$L$1022, 3, FALSE) -> ÁLGEBRA | C29: =VLOOKUP(O29,[2]ASIGNATURAS!$F$1:$L$1022, 4, FALSE) -> Álgebra y Ecuaciones Diferenciales | O29: 6303 | S29: =VLOOKUP(O29,[2]ASIGNATURAS!$F$1:$L$1022, 5, FALSE) -> 6 | U29: =VLOOKUP(O29,[2]ASIGNATURAS!$F$1:$L$1022, 6, FALSE) -> José Javier Relancio | AQ29: GR. PRÁCTICOS
A30: =VLOOKUP(O30,[2]ASIGNATURAS!$F$1:$L$1022, 3, FALSE) -> FÍSICA I | C30: =VLOOKUP(O30,[2]ASIGNATURAS!$F$1:$L$1022, 4, FALSE) -> Física I | O30: 6304 | S30: =VLOOKUP(O30,[2]ASIGNATURAS!$F$1:$L$1022, 5, FALSE) -> 6 | U30: =VLOOKUP(O30,[2]ASIGNATURAS!$F$1:$L$1022, 6, FALSE) -> Juan José Villalaín, Alfonso Blasco, María del Mar Chichón | AQ30: (101)
A31: =VLOOKUP(O31,[2]ASIGNATURAS!$F$1:$L$1022, 3, FALSE) -> QUÍMICA | C31: =VLOOKUP(O31,[2]ASIGNATURAS!$F$1:$L$1022, 4, FALSE) -> Química | O31: 6305 | S31: =VLOOKUP(O31,[2]ASIGNATURAS!$F$1:$L$1022, 5, FALSE) -> 6 | U31: =VLOOKUP(O31,[2]ASIGNATURAS!$F$1:$L$1022, 6, FALSE) -> Fco. Javier Rodríguez | AQ31: (102)
A32: =VLOOKUP(O32,[2]ASIGNATURAS!$F$1:$L$1022, 3, FALSE) -> EXP. GRÁFICA I | C32: =VLOOKUP(O32,[2]ASIGNATURAS!$F$1:$L$1022, 4, FALSE) -> Expresión Gráfica I | O32: 6306 | S32: =VLOOKUP(O32,[2]ASIGNATURAS!$F$1:$L$1022, 5, FALSE) -> 6 | U32: =VLOOKUP(O32,[2]ASIGNATURAS!$F$1:$L$1022, 6, FALSE) -> Arturo de Román , Elías Martínez | AQ32: (103)(104)(105)
A33: Nota: Estos horarios podrán ser modificados por necesidades docentes (desdoble de grupos, ocupación de laboratorios, contratación de profesorado…)
A34: =VLOOKUP(A37,ASIGNATURAS!$A$2:$D$151, 3, FALSE) -> 1º Grado en Ingeniería Mecánica | AP34: =Aulas!G5 -> Curso 2024-2025
A35: =VLOOKUP(A37,ASIGNATURAS!$A$2:$D$151, 2, FALSE) -> Semestre temporal: 2º (2º Semestre Académico) | AP35: Aula 51-A1
A36: Grupo 1: MANAÑA
A37: GIM_2
A38: Hora | B38: LUNES | L38: MARTES | V38: MIÉRCOLES | AF38: JUEVES | AP38: VIERNES
A39: 08:30 - 09:30 | B39: (101) | C39: Lab 46-A1 | F39: (103) | G39: Lab. Fisica / Aula 31-A2 | L39: (101) | M39: Lab. Fisica / Aula 31-A2 | V39: (101) | W39: Aula 32-A1 (Inf.)/Aula 42-A2 | AB39: (104) | AC39: Lab. Fisica / Aula 36-A2 | AH39: (102) | AI39: Lab. Materiales | AJ39: (103) | AK39: Aula 54-A1 | AP39: (101) | AQ39: Aula 54-A1 | AR39: (102) | AS39: Lab 46-A1 | AT39: (103) | AU39: Aula 32-A1 (Inf.)/Aula 42-A2
B40: INFORMATICA | F40: FISICA II | L40: FISICA II | V40: AMP. CALC. | AB40: FISICA II | AH40: MATERIALES | AJ40: ECONOMIA | AP40: ECONOMIA | AR40: INFORMATICA | AT40: AMP. CALC.
A41: 09:30 - 10:30
A43: 10:30 - 11:30 | B43: MATERIALES | H43: Aula 51-A1 | L43: INFORMATICA | R43: Aula 51-A1 | V43: MATERIALES | AB43: Aula 51-A1 | AF43: AMP. CÁLCULO | AL43: Aula 51-A1 | AP43: ECONOMÍA | AV43: Aula 51-A1
A45: 11:30 - 12:30 | B45: FISICA II | H45: Aula 51-A1 | L45: FISICA II | R45: Aula 51-A1 | V45: AMP. CALC. | AB45: Aula 51-A1 | AF45: ECONOMÍA | AL45: Aula 51-A1 | AP45: INFORMÁTICA | AV45: Aula 51-A1
...

Sheet GIOI
A1: =VLOOKUP(A4,ASIGNATURAS!$A$2:$D$151, 3, FALSE) -> 1º Grado en Ingeniería de Organización Industrial | Z1: =Aulas!G5 -> Curso 2024-2025
A2: =VLOOKUP(A4,ASIGNATURAS!$A$2:$D$151, 2, FALSE) -> Semestre temporal: 1º (1º Semestre Académico) | Z2: Aula 52-A1
A3: Grupo: MANAÑA
A4: GIO_1
A5: Hora | B5: LUNES | H5: MARTES | N5: MIÉRCOLES | T5: JUEVES | Z5: VIERNES
A6: 08:30 - 09:30 | B6: INFORMATICA | H6: QUIMICA | N6: QUIMICA | T6: INFORMATICA | Z6: EXP. GRAFICA I
B7: Aula 52-A1 | H7: Aula 52-A1 | N7: Aula 52-A1 | T7: Aula 52-A1 | Z7: Aula 41-A2
A8: 09:30 - 10:30 | B8: CALCULO | H8: FISICA I | N8: FISICA I | T8: CALCULO | Z8: (101) | AA8: Aula 53-A2 (CAD) / 41-A2 (Tab) | AD8: (103) | AE8: Aula 55-A2 (CAD) / 41-A2 (Tab)
B9: Aula 52-A1 | H9: Aula 52-A1 | N9: Aula 52-A1 | T9: Aula 52-A1 | Z9: EXP. GRAFICA I | AD9: EXP. GRAFICA I
A10: 10:30 - 11:30 | B10: (101) | C10: Lab 46-A1 | D10: (102) | E10: Aula 51-A2 (Inf.) | H10: (101) | I10: Lab. Química | J10: (102) | K10: Lab. Fisica / Aula 31-A2 | L10: (103) | M10: Aula 51-A2 (Inf.) | N10: (101) | O10: Lab. Fisica / Aula 31-A2 | V10: DRAWING I
B11: INFORMATICA | D11: CALCULO | H11: QUIMICA | J11: FISICA I | L11: CALCULO | N11: FISICA I | V11: Aula 53-A2 (CAD)
A12: 11:30 - 12:30 | V12: (801) | W12: Aula 53-A2 (CAD) / 41-A2 (Tab)
V13: DRAWING I
A14: 12:30 - 13:30 | B14: (101) | C14: Aula 51-A2 (Inf.) | D14: (102) | E14: Lab 46-A1 | L14: (102) | M14: Lab. Química
B15: CALCULO | D15: INFORMATICA | L15: QUIMICA
A16: 13:30 - 14:30
A19: Nombre abreviado | C19: Nombre completo | M19: GIO__1 | O19: ECTS | Q19: Profesor / es
A20: =VLOOKUP(M20,ASIGNATURAS!$F$1:$L$1022, 3, FALSE) -> CALCULO | C20: =VLOOKUP(M20,ASIGNATURAS!$F$1:$L$1022, 4, FALSE) -> Cálculo | M20: 9115 | O20: =VLOOKUP(M20,ASIGNATURAS!$F$1:$L$1022, 5, FALSE) -> 6 | Q20: =VLOOKUP(M20,ASIGNATURAS!$F$1:$L$1022, 6, FALSE) -> Jose Luis Fernández, Silvia Alvárez de Eulate
A21: =VLOOKUP(M21,ASIGNATURAS!$F$1:$L$1022, 3, FALSE) -> FISICA I | C21: =VLOOKUP(M21,ASIGNATURAS!$F$1:$L$1022, 4, FALSE) -> Física I | M21: 9116 | O21: =VLOOKUP(M21,ASIGNATURAS!$F$1:$L$1022, 5, FALSE) -> 6 | Q21: =VLOOKUP(M21,ASIGNATURAS!$F$1:$L$1022, 6, FALSE) -> María del Mar Chichón González
A22: =VLOOKUP(M22,ASIGNATURAS!$F$1:$L$1022, 3, FALSE) -> EXP. GRAFICA I | C22: =VLOOKUP(M22,ASIGNATURAS!$F$1:$L$1022, 4, FALSE) -> Expresión Gráfica E/I (Español/Inglés) | M22: 9117 | O22: =VLOOKUP(M22,ASIGNATURAS!$F$1:$L$1022, 5, FALSE) -> 6 | Q22: =VLOOKUP(M22,ASIGNATURAS!$F$1:$L$1022, 6, FALSE) -> M. Esther Baños García, Esteban García
A23: =VLOOKUP(M23,ASIGNATURAS!$F$1:$L$1022, 3, FALSE) -> INFORMATICA | C23: =VLOOKUP(M23,ASIGNATURAS!$F$1:$L$1022, 4, FALSE) -> Informática Básica | M23: 9118 | O23: =VLOOKUP(M23,ASIGNATURAS!$F$1:$L$1022, 5, FALSE) -> 6 | Q23: =VLOOKUP(M23,ASIGNATURAS!$F$1:$L$1022, 6, FALSE) -> Ángel Arroyo Puente,
A24: =VLOOKUP(M24,ASIGNATURAS!$F$1:$L$1022, 3, FALSE) -> QUIMICA | C24: =VLOOKUP(M24,ASIGNATURAS!$F$1:$L$1022, 4, FALSE) -> Química | M24: 9119 | O24: =VLOOKUP(M24,ASIGNATURAS!$F$1:$L$1022, 5, FALSE) -> 6 | Q24: =VLOOKUP(M24,ASIGNATURAS!$F$1:$L$1022, 6, FALSE) -> Luis Marcos Naveira
A27: GRUPOS TEÓRICOS = 1/2
A28: GRUPOS PRÁCTICOS = 3
A29: Los alumnos bilingües y los repetidores,tienen que coger el grupo de prácticas 102 para las asignaturas "solo" en español
A32: Nota: Estos horarios podrán ser modificados por necesidades docentes (desdoble de grupos, ocupación de laboratorios, contratación de profesorado…)
A34: =VLOOKUP(A37,ASIGNATURAS!$A$2:$D$151, 3, FALSE) -> 1º Grado en Ingeniería de Organización Industrial | Z34: =Z1 -> Curso 2024-2025
A35: =VLOOKUP(A37,ASIGNATURAS!$A$2:$D$151, 2, FALSE) -> Semestre temporal: 2º (2º Semestre Académico) | Z35: Aula 52A1/32 A2
A36: Grupo: MANAÑA
A37: GIO_2
A38: Hora | B38: LUNES | H38: MARTES | N38: MIÉRCOLES | T38: JUEVES | Z38: VIERNES
A39: 08:30 - 09:30 | D39: (801) | E39: Lab. Materiales | H39: ALGEBRA | N39: AMP. CALCULO | T39: AMP. CALCULO | Z39: MATERIALES | AC39: ENG. MATERIALS
D40: ENG. MATERIALS | H40: Aula 52-A1 | N40: Aula 52-A1 | T40: Aula 52-A1 | Z40: Aula 52-A1 | AC40: Aula 32-A2
A41: 09:30 - 10:30 | H41: ALGEBRA | N41: FISICA II | T41: FISICA II | Z41: MATERIALES | AC41: ENG. MATERIALS
H42: Aula 52-A1 | N42: Aula 52-A1 | T42: Aula 52-A1 | Z42: Aula 52-A1 | AC42: Aula 32-A2
A43: 10:30 - 11:30 | B43: (101) | C43: Lab. Fisica / Aula 34-A2 | F43: (103) | G43: Aula Inf. 2B / Aula 42-A2 | H43: ECONOMIA | N43: (101) | O43: Aula 33-A2 / 32-A1(Inf.) | P43: (102) | Q43: Aula 51-A2 / Aula 31-A2 | R43: (103) | S43: Lab. Fisica / Aula 34-A2 | T43: (101) | U43: Aula 51-A2 / Aula 31-A2 | V43: (102) | W43: Lab. Fisica / Aula 34-A2 | X43: (103) | Y43: Aula 42-A2 / 32-A1(Inf.) | AD43: (103) | AE43: Aula 51-A2 / Aula 31-A2
B44: FISICA II | F44: ECONOMIA | H44: Aula 31-A2 | N44: ALGEBRA | P44: AMP. CALCULO | R44: FISICA II | T44: AMP. CALCULO | V44: FISICA II | X44: ALGEBRA | AD44: AMP. CALCULO
A45: 11:30 - 12:30 | H45: ECONOMIA
H46: Aula 31-A2
A47: 12:30 - 13:30 | B47: (101) | C47: Aula Inf. 2B / Aula 42-A2 | P47: (102) | Q47: Aula 34-A2 / 32-A1(Inf.) | X47: (101) | Y47: Lab. Materiales
...

Sheet D_GIM-GIEIA 
A1: 1º Doble Grado en Ingeniería Mecánica e Ingeniería Electrónica Industrial y Automática | Z1: =Aulas!G5 -> Curso 2024-2025
A2: Semestre temporal: 1º (PRIMER SEMESTRE ACADÉMICO) | Z2: Aula 33-A2
A3: Grupo: MANAÑA
A4: DOB_1
A5: Hora | B5: LUNES | H5: MARTES | N5: MIÉRCOLES | T5: JUEVES | Z5: VIERNES
A6: 08:30 - 09:30 | H6: CALCULO | N6: QUIMICA | T6: EXP. GRAFICA I
H7: Aula 33-A2 / Aula 52-A2(Inf.) | N7: Lab. Química / Aula 33-A2 | T7: Aula 55-A2 (CAD) / 41-A2 (Tab)
A8: 9:30 - 10:30 | H8: CALCULO | N8: QUIMICA | T8: EXP. GRAFICA I
H9: Aula 33-A2 / Aula 52-A2(Inf.) | N9: Lab. Química / Aula 33-A2 | T9: Aula 55-A2 (CAD) / 41-A2 (Tab)
A10: 10:30 - 11:30 | B10: FISICA I | H10: QUIMICA | N10: ALGEBRA | T10: EXP. GRAFICA I
B11: Aula 33-A2 | H11: Aula 33-A2 | N11: Aula 33-A2 | T11: Aula 55-A2 (CAD) / 41-A2 (Tab)
A12: 11:30 - 12:30 | B12: FÍSICA I | H12: QUIMICA | N12: ALGEBRA | T12: EXP. GRAFICA I
B13: Aula 33-A2 | H13: Aula 33-A2 | N13: Aula 33-A2 | T13: Aula 55-A2 (CAD) / 41-A2 (Tab)
A14: 12:30 - 13:30 | B14: CALCULO | H14: FISICA I | T14: ALGEBRA
B15: Aula 33-A2 | H15: Lab. Fisica / Aula 33-A2 | T15: Aula 51-A2 (Inf.) / 33-A2
A16: 13:30 - 14:30 | B16: CALCULO | H16: FISICA I | T16: ALGEBRA
B17: Aula 33-A2 | H17: Lab. Fisica / Aula 33-A2 | T17: Aula 51-A2 (Inf.) / 33-A2
A20: Nombre abreviado | C20: Nombre completo | M20: Codigo | O20: ECTS | Q20: Profesor / es
A21: CALCULO | C21: =ASIGNATURAS!I259 -> Cálculo | M21: 7711 | O21: 6 | Q21: =ASIGNATURAS!K259 -> Elena Cebrián de Barrio
A22: ALGEBRA | C22: =ASIGNATURAS!I260 -> Álgebra y Ecuaciones Diferenciales | M22: 7712 | O22: 6 | Q22: =ASIGNATURAS!K260
A23: FISICA I | C23: =ASIGNATURAS!I261 -> Física I | M23: 7713 | O23: 6 | Q23: =ASIGNATURAS!K261 -> Juan José Villalaín ,
A24: QUIMICA | C24: =ASIGNATURAS!I262 -> Química | M24: 7714 | O24: 6 | Q24: =ASIGNATURAS!K262 -> Indalecio Peñacoba, Francisco Javier Rodriguez ,
A25: EXP. GRAF. I | C25: =ASIGNATURAS!I263 -> Expresión Gráfica I | M25: 7715 | O25: 6 | Q25: =ASIGNATURAS!K263 -> Arturo de Román Miguel, Elías Martínez
A28: GRUPOS TEÓRICOS = 1
A29: GRUPOS PRÁCTICOS = 1
A31: Nota: Estos horarios podrán ser modificados por necesidades docentes (desdoble de grupos, ocupación de laboratorios, contratación de profesorado…)
A32: Por necesidades docentes las clases de Cálculo pasan a horario de tarde
A34: 1º Doble Grado en Ingeniería Mecánica e Ingeniería Electrónica Industrial y Automática | Z34: =Z1 -> Curso 2024-2025
A35: Semestre temporal: 2º (SEGUNDO SEMESTRE ACADÉMICO) | Z35: Aula 33-A2
A36: Grupo: MANAÑA
A37: DOB_2
A38: Hora | B38: LUNES | H38: MARTES | N38: MIÉRCOLES | T38: JUEVES | Z38: VIERNES
A39: 08:30 - 09:30 | B39: ECONOMIA | H39: ECONOMIA | N39: FISICA II | T39: EXP. GRAFICA II
B40: Aula 21-A1 | H40: Aula 21-A1 | N40: Aula 33-A2 | T40: Aula 41-A2
A41: 9:30 - 10:30 | B41: ECONOMIA | H41: ECONOMIA | N41: FISICA II | T41: INFORMATICA
B42: Aula 21-A1 | H42: Aula 21-A1 | N42: Aula 33-A2 | T42: Aula 33-A2
A43: 10:30 - 11:30 | B43: EXP. GRAFICA II | H43: FISICA II | N43: INFORMATICA | T43: CIENCIA DE MATERIALES | Z43: AMP. CALCULO
B44: Aula 55-A2 (CAD) / 41-A2 (Tab) | H44: Lab. Fisica / Aula 33-A2 | N44: Lab 46-A1 | T44: Lab. Materiales | Z44: Aula 52-A2 (Inf.)
A45: 11:30 - 12:30 | B45: EXP. GRAFICA II | H45: FISICA II | N45: INFORMATICA | T45: CIENCIA DE MATERIALES | Z45: AMP. CALCULO
B46: Aula 55-A2 (CAD) / 41-A2 (Tab) | H46: Lab. Fisica / Aula 33-A2 | N46: Lab 46-A1 | T46: Lab. Materiales | Z46: Aula 52-A2 (Inf.)
...

Sheet GII (primero)
A1: =VLOOKUP(A4,ASIGNATURAS!$A$2:$D$151, 3, FALSE) -> 1º Grado en Ingeniería Informática | AT1: =Aulas!G5 -> Curso 2024-2025
A2: =VLOOKUP(A4,ASIGNATURAS!$A$2:$D$151, 2, FALSE) -> Semestre temporal: 1º (1º Semestre Académico) | AT2: Aula 53,54A1
A3: Grupo: MANAÑA
A4: GII_1
A5: Hora | B5: LUNES | N5: MARTES | Z5: MIÉRCOLES | AJ5: JUEVES | AT5: VIERNES
A6: 08:30 - 09:30 | B6: FUND. FÍSICOS | J6: Aula 53-A1 | M6: 1 | N6: MAT DISCRETA | V6: Aula 53-A1 | Y6: 1 | Z6: INFORMÁTICA | AF6: Aula 53-A1 | AI6: 1 | AJ6: FUND. TICS | AP6: Aula 53-A1 | AS6: 1 | AT6: ÁLGEBRA | AZ6: Aula 53-A1 | BC6: 1
B7: FUND. TICS | J7: Aula 54-A1 | M7: 2 | N7: INFORMÁTICA | V7: Aula 54-A1 | Y7: 2 | Z7: MAT DISCRETA | AF7: Aula 54-A1 | AI7: 2 | AJ7: FUND. FÍSICOS | AP7: Aula 54-A1 | AS7: 2 | AT7: ÁLGEBRA | AZ7: Aula 54-A1 | BC7: 2
A8: 09:30 - 10:30 | B8: INFORMÁTICA | J8: Aula 53-A1 | M8: 1 | N8: FUND. TICS | V8: Aula 53-A1 | Y8: 1 | Z8: ÁLGEBRA | AF8: Aula 53-A1 | AI8: 1 | AJ8: MAT DISCRETA | AP8: Aula 53-A1 | AS8: 1 | AT8: FUND. FÍSICOS | AZ8: Aula 53-A1 | BC8: 1
B9: MAT DISCRETA | J9: Aula 54-A1 | M9: 2 | N9: FUND. FÍSICOS | V9: Aula 54-A1 | Y9: 2 | Z9: ÁLGEBRA | AF9: Aula 54-A1 | AI9: 2 | AJ9: INFORMÁTICA | AP9: Aula 54-A1 | AS9: 2 | AT9: FUND. TICS | AZ9: Aula 54-A1 | BC9: 2
A10: 10:30 - 11:30 | B10: (101) | C10: Lab. 22-A1 | F10: (103) | G10: Lab 44-A1 | H10: (201) | I10: Lab. Fisica / Aula 46-A2 | P10: (102) | Q10: Lab. 22-A1 | R10: (103) | S10: Lab. 32-A1 | T10: (201) | U10: Lab 44-A1 | Z10: (101) | AA10: Lab 44-A1 | AB10: (102) | AC10: Lab. Fisica / Aula 46-A2 | AD10: (103) | AE10: Aula 52-A2 (Inf.) | AF10: (201) | AG10: Lab. 32-A1 | AH10: (202) | AI10: Aula 51-A2 (Inf.) | AJ10: (101) | AK10: Aula Inf. 2B | AL10: (102) | AM10: Lab. 32-A1 | AN10: (103) | AO10: Lab. Fisica / Aula 46-A2 | AP10: (201) | AQ10: Lab. 22-A1 | AR10: (202) | AS10: Lab 44-A1 | AT10: (101) | AU10: Lab. Fisica / Aula 46-A2 | AV10: (102) | AW10: Lab 44-A1 | BB10: (202) | BC10: Lab. 22-A1
B11: FUND. TICS | F11: INFORMÁTICA | H11: FUND. FÍSICOS | P11: FUND. TICS | R11: MAT DISCRETA | T11: INFORMÁTICA | Z11: INFORMÁTICA | AB11: FUND. FÍSICOS | AD11: ALGEBRA | AF11: MAT DISCRETA | AH11: ALGEBRA | AJ11: ALGEBRA | AL11: MAT DISCRETA | AN11: FUND. FISICOS | AP11: FUND. TICS | AR11: INFORMÁTICA | AT11: FUND. FÍSICOS | AV11: INFORMÁTICA | BB11: FUND. TICS
A12: 11:30 - 12:30
A14: 12:30 - 13:30 | R14: (103) | S14: Lab. 22-A1 | AF14: (201) | AG14: Aula 52-A2 (Inf.) | AH14: (202) | AI14: Lab. Fisica / Aula 46-A2 | AL14: (102) | AM14: Aula 52-A2 (Inf.)
R15: FUND. TICS | AF15: ALGEBRA | AH15: FUND. FÍSICOS | AL15: ALGEBRA
A16: 13:30 - 14:30
A18: Hora | B18: LUNES | N18: MARTES | Z18: MIÉRCOLES | AJ18: JUEVES | AT18: VIERNES
A19: 16:30 - 17:30 | V19: (202) | W19: Lab. 32-A1 | Z19: (101) | AA19: Lab. 32-A1 MAT
V20: MAT DISCRETA | Z20: MAT DISCRETA
A21: 17:30 - 18:30
A24: Nombre abreviado | F24: Nombre completo | Z24: GII__1 | AD24: ECTS | AH24: Profesor / es
A25: ÁLGEBRA | F25: =VLOOKUP(Z25,ASIGNATURAS!$F$1:$L$1022, 4, FALSE) -> Álgebra Lineal | Z25: 8797 | AD25: =VLOOKUP(Z25,ASIGNATURAS!$F$1:$L$1022, 5, FALSE) -> 6 | AH25: =VLOOKUP(Z25,ASIGNATURAS!$F$1:$L$1022, 6, FALSE) -> Mª Begoña Torres, Zaíra Pérez
A26: INFORMÁTICA | F26: =VLOOKUP(Z26,ASIGNATURAS!$F$1:$L$1022, 4, FALSE) -> Informática Básica | Z26: 8798 | AD26: =VLOOKUP(Z26,ASIGNATURAS!$F$1:$L$1022, 5, FALSE) -> 6 | AH26: =VLOOKUP(Z26,ASIGNATURAS!$F$1:$L$1022, 6, FALSE) -> Virginia Martínez, Mario Martínez
A27: FUND. FÍSICOS | F27: =VLOOKUP(Z27,ASIGNATURAS!$F$1:$L$1022, 4, FALSE) -> Fundamentos Físicos de la Informática | Z27: 8799 | AD27: =VLOOKUP(Z27,ASIGNATURAS!$F$1:$L$1022, 5, FALSE) -> 6 | AH27: =VLOOKUP(Z27,ASIGNATURAS!$F$1:$L$1022, 6, FALSE) -> Fernando Manuel García, Alfredo Bol
A28: MAT DISCRETA | F28: =VLOOKUP(Z28,ASIGNATURAS!$F$1:$L$1022, 4, FALSE) -> Matemática Discreta | Z28: 8800 | AD28: =VLOOKUP(Z28,ASIGNATURAS!$F$1:$L$1022, 5, FALSE) -> 6 | AH28: =VLOOKUP(Z28,ASIGNATURAS!$F$1:$L$1022, 6, FALSE) -> Mª Pilar de las Heras, Alfredo Gordillo
A29: FUND. TICS | F29: =VLOOKUP(Z29,ASIGNATURAS!$F$1:$L$1022, 4, FALSE) -> Fund. Deont. y Jurídicos de las TICs | Z29: 8796 | AD29: =VLOOKUP(Z29,ASIGNATURAS!$F$1:$L$1022, 5, FALSE) -> 6 | AH29: =VLOOKUP(Z29,ASIGNATURAS!$F$1:$L$1022, 6, FALSE) -> Mª del Rosario González, Rosa Sánchez
A30: Nota: Estos horarios podrán ser modificados por necesidades docentes (desdoble de grupos, ocupación de laboratorios, contratación de profesorado…)
A34: =VLOOKUP(A37,ASIGNATURAS!$A$2:$D$151, 3, FALSE) -> 1º Grado en Ingeniería Informática | AT34: =AT1 -> Curso 2024-2025
A35: =VLOOKUP(A37,ASIGNATURAS!$A$2:$D$151, 2, FALSE) -> Semestre temporal: 2º (2º Semestre Académico) | AT35: Aula 51/53 A1
A36: Grupo: MANAÑA
A37: GII_2
A38: Hora | B38: LUNES | N38: MARTES | Z38: MIÉRCOLES | AJ38: JUEVES | AT38: VIERNES
A39: 08:30 - 09:30 | B39: INGLÉS | J39: Aula 51-A1 | M39: 1 | N39: COMPUTADORES | V39: Aula 51-A1 | Y39: 1 | Z39: INGLÉS | AF39: Aula 51-A1 | AI39: 1 | AJ39: SIST. OPERATIV. | AP39: Aula 53-A1 | AS39: 1 | AT39: CÁLCULO | AZ39: Aula 53-A1 | BC39: 1
B40: INGLÉS | J40: Aula 51-A1 | M40: 2 | N40: COMPUTADORES | V40: Aula 51-A1 | Y40: 2 | Z40: INGLÉS | AF40: Aula 51-A1 | AI40: 2 | AJ40: CÁLCULO | AP40: Aula 51-A1 | AS40: 2 | AT40: PROGRAMACIÓN | AZ40: Aula 51-A1 | BC40: 2
A41: 09:30 - 10:30 | B41: PROGRAMACION | J41: Aula 53-A1 | M41: 1 | N41: CÁLCULO | V41: Aula 53-A1 | Y41: 1 | Z41: PROGRAMACIÓN | AF41: Aula 53-A1 | AI41: 1 | AJ41: COMPUTADORES | AP41: Aula 51-A1 | AS41: 1 | AT41: SIST. OPERATIV. | AZ41: Aula 53-A1 | BC41: 1
B42: SIST. OPERATIV. | J42: Aula 51-A1 | M42: 2 | N42: PROGRAMACIÓN | V42: Aula 51-A1 | Y42: 2 | Z42: SIST. OPERATIV. | AF42: Aula 51-A1 | AI42: 2 | AJ42: COMPUTADORES | AP42: Aula 51-A1 | AS42: 2 | AT42: CÁLCULO | AZ42: Aula 51-A1 | BC42: 2
A43: 10:30 - 11:30 | B43: (101) | C43: Aula 51-A2 (Inf.) | D43: (102) | E43: Aula 31-A2 | F43: (103) | G43: Lab 42-A1 | J43: (203) | K43: Lab 44-A1 | L43: (202) | M43: Aula 44-A2 | N43: (101) | O43: Lab 44-A1 | T43: (201) | U43: Aula 44-A2 | V43: (202) | W43: Lab. Electrónica 3 | Z43: (101) | AA43: Aula 44-A2 | AD43: (201) | AE43: Lab. Electrónica 3 | AH43: (202) | AI43: Lab 44-A1 | AL43: (102) | AM43: Lab. Electrónica 3 | AN43: (103) | AO43: Lab 44-A1 | AP43: (201) | AQ43: Aula 52-A2 (Inf.) | AV43: (102) | AW43: Lab 44-A1 | BB43: (202) | BC43: Lab 42-A1
B44: CÁLCULO | D44: INGLÉS | F44: SIST. OPERATIV. | J44: PROGRAMACIÓN | L44: INGLÉS | N44: PROGRAMACIÓN | T44: INGLÉS | V44: COMPUTADORES | Z44: INGLÉS | AD44: COMPUTADORES | AH44: PROGRAMACIÓN | AL44: COMPUTADORES | AN44: PROGRAMACIÓN | AP44: CÁLCULO | AV44: PROGRAMACIÓN | BB44: SIST. OPERATIV.
A45: 11:30 - 12:30
A47: 12:30 - 13:30 | B47: (101) | C47: Lab 42-A1 | D47: (102) | E47: Aula 51-A2 (Inf.) | L47: (202) | M47: Aula 51-A2 (Inf.) | T47: (201) | U47: Lab 42-A1 | Z47: (101) | AA47: Lab. Electrónica 3 | AL47: (102) | AM47: Lab 42-A1 | AN47: (103) | AO47: Aula 52-A2 (Inf.) | AP47: (201) | AQ47: Lab 44-A1
B48: SIST. OPERATIV. | D48: CÁLCULO | L48: CÁLCULO | T48: SIST. OPERATIV. | Z48: COMPUTADORES | AL48: SIST. OPERATIV. | AN48: CÁLCULO | AP48: PROGRAMACIÓN
...

Sheet GII 
A1: =VLOOKUP(A4,ASIGNATURAS!$A$2:$D$151, 3, FALSE) -> 2º Grado en Ingeniería Informática | AP1: ='GII (primero)'!AT34 -> Curso 2024-2025
A2: =VLOOKUP(A4,ASIGNATURAS!$A$2:$D$151, 2, FALSE) -> Semestre temporal: 1º (3º Semestre Académico) | AP2: Aula 51A1
A3: Grupo: TARDE
A4: GII_3
A5: Hora | B5: LUNES | L5: MARTES | V5: MIÉRCOLES | AF5: JUEVES | AP5: VIERNES
A6: 14:30 - 15:30 | B6: (101) | C6: Lab 44-A1 | F6: (103) | G6: Lab 46-A1 | L6: (201) | M6: Lab Electrónica 3 | N6: (102) | O6: Lab. 32-A1 | P6: (103) | Q6: Aula 51-A2 (Inf.) | V6: (101) | W6: Lab. 32-A1 | X6: (102) | Y6: Lab Electrónica 3 | Z6: (103) | AA6: Lab 44-A1 | AL6: (202) | AM6: Lab 46-A1
B7: BASES DATOS | F7: MET. PROG. | L7: ARQUITEC. COMP. | N7: ESTADISTÍCA | P7: ESTADISTÍCA | V7: ESTADISTÍCA | X7: ARQUITEC. COMP. | Z7: BASES DATOS | AL7: MET. PROG.
A8: 15:30 - 16:30
A10: 16:30 - 17:30 | B10: MET. PROG. | H10: Aula 53-A1 | K10: 1 | L10: ARQUIT. COMP. | R10: Aula 51-A1 | U10: 1 | V10: ESTADISTÍCA | AB10: Aula 53-A1 | AE10: 1 | AF10: ARQUIT. COMP. | AL10: Aula 51-A1 | AO10: 1 | AP10: ESTADISTÍCA | AV10: Aula 53-A1 | AY10: 1
B11: BASES DATOS | H11: Aula 51-A1 | K11: 2 | L11: ARQUIT. COMP. | R11: Aula 51-A1 | U11: 2 | V11: ESTADISTÍCA | AB11: Aula 51-A1 | AE11: 2 | AF11: ARQUIT. COMP. | AL11: Aula 51-A1 | AO11: 2 | AP11: ESTADISTÍCA | AV11: Aula 51-A1 | AY11: 2
A12: 17:30 - 18:30 | B12: BASES DATOS | H12: Aula 53-A1 | K12: 1 | L12: SOFTWARE | R12: Aula 51-A1 | U12: 1 | V12: BASES DATOS | AB12: Aula 53-A1 | AE12: 1 | AF12: SOFTWARE | AL12: Aula 51-A1 | AO12: 1 | AP12: MET. PROG. | AV12: Aula 53-A1 | AY12: 1
B13: MET. PROG. | H13: Aula 51-A1 | K13: 2 | L13: SOFTWARE | R13: Aula 51-A1 | U13: 2 | V13: MET. PROG. | AB13: Aula 51-A1 | AE13: 2 | AF13: SOFTWARE | AL13: Aula 51-A1 | AO13: 2 | AP13: BASES DATOS | AV13: Aula 51-A1 | AY13: 2
A14: 18:30 - 19:30 | B14: (101) | C14: Aula Inf. 1B | D14: (102) | E14: Lab 44-A1 | H14: (201) | I14: Lab 46-A1 | J14: (202) | K14: Lab. 32-A1 | L14: (101) | M14: Lab 46-A1 | N14: (102) | O14: Lab. 24-A1 | R14: (201) | S14: Lab 44-A1 | T14: (202) | U14: Lab Electrónica 3 | Z14: (202) | AA14: Lab. 24-A1 | AB14: (101) | AC14: Lab Electrónica 3 | AD14: (201) | AE14: Lab 46-A1 | AH14: (102) | AI14: Lab 44-A1 | AJ14: (103) | AK14: Lab Electrónica 3 | AL14: (201) | AM14: Lab. 32-A1 | AN14: (202) | AO14: Lab 46-A1
B15: MET. PROG. | D15: BASES DATOS | H15: SOFTWARE | J15: ESTADISTÍCA | L15: SOFTWARE | N15: SOFTWARE | R15: BASES DATOS | T15: ARQUITEC. COMP. | Z15: SOFTWARE | AB15: ARQUITEC. COMP. | AD15: MET. PROG. | AH15: MET. PROG. | AJ15: ARQUIT. COMP. | AL15: ESTADISTÍCA | AN15: BASES DATOS
A16: 19:30 - 20:30
A19: Nombre abreviado | C19: Nombre completo | U19: GII__3 | W19: ECTS | AA19: Profesor / es
A20: =VLOOKUP(U20,ASIGNATURAS!$F$1:$L$1022, 3, FALSE) -> MET. PROG. | C20: =VLOOKUP(U20,ASIGNATURAS!$F$1:$L$1022, 4, FALSE) -> Metodología de la Programación | U20: 8806 | W20: =VLOOKUP(U20,ASIGNATURAS!$F$1:$L$1022, 5, FALSE) -> 6 | AA20: =VLOOKUP(U20,ASIGNATURAS!$F$1:$L$1022, 6, FALSE) -> Raúl Marticorena Sánchez
A21: =VLOOKUP(U21,ASIGNATURAS!$F$1:$L$1022, 3, FALSE) -> ESTADISTÍCA | C21: =VLOOKUP(U21,ASIGNATURAS!$F$1:$L$1022, 4, FALSE) -> Estadística | U21: 8807 | W21: =VLOOKUP(U21,ASIGNATURAS!$F$1:$L$1022, 5, FALSE) -> 6 | AA21: =VLOOKUP(U21,ASIGNATURAS!$F$1:$L$1022, 6, FALSE) -> Diego Sedano, Alvaro Díez
A22: =VLOOKUP(U22,ASIGNATURAS!$F$1:$L$1022, 3, FALSE) -> SOFTWARE | C22: =VLOOKUP(U22,ASIGNATURAS!$F$1:$L$1022, 4, FALSE) -> Ingeniería del Software | U22: 8808 | W22: =VLOOKUP(U22,ASIGNATURAS!$F$1:$L$1022, 5, FALSE) -> 6 | AA22: =VLOOKUP(U22,ASIGNATURAS!$F$1:$L$1022, 6, FALSE) -> Jorge San Miguel Navazo, Belén Vaquerizo
A23: =VLOOKUP(U23,ASIGNATURAS!$F$1:$L$1022, 3, FALSE) -> BASES DATOS | C23: =VLOOKUP(U23,ASIGNATURAS!$F$1:$L$1022, 4, FALSE) -> Bases de Datos | U23: 8809 | W23: =VLOOKUP(U23,ASIGNATURAS!$F$1:$L$1022, 5, FALSE) -> 6 | AA23: =VLOOKUP(U23,ASIGNATURAS!$F$1:$L$1022, 6, FALSE) -> Jesús Manuel Maudes Raedo
A24: =VLOOKUP(U24,ASIGNATURAS!$F$1:$L$1022, 3, FALSE) -> ARQUIT. COMP. | C24: =VLOOKUP(U24,ASIGNATURAS!$F$1:$L$1022, 4, FALSE) -> Arquitectura de Computadores | U24: 8810 | W24: =VLOOKUP(U24,ASIGNATURAS!$F$1:$L$1022, 5, FALSE) -> 6 | AA24: =VLOOKUP(U24,ASIGNATURAS!$F$1:$L$1022, 6, FALSE) -> César Represa Pérez, Ana Serna
A27: GRUPOS TEORICOS = 2
A28: GRUPOS PRÁCTICOS = 4/5
A30: Grupos prácticos en la Matrícula y en horarios: 104 matrícula equivale al 201 en horarios, 105 equivale al 202, el 103 en matrícula solo está en horario para bases de datos, arquitectura de ccomputadores y metodología de la programación
A31: Nota: Estos horarios podrán ser modificados por necesidades docentes (desdoble de grupos, ocupación de laboratorios, contratación de profesorado…)
A34: =VLOOKUP(A37,ASIGNATURAS!$A$2:$D$151, 3, FALSE) -> 2º Grado en Ingeniería Informática | AP34: =AP1 -> Curso 2024-2025
A35: =VLOOKUP(A37,ASIGNATURAS!$A$2:$D$151, 2, FALSE) -> Semestre temporal: 2º (4º Semestre Académico) | AP35: Aula 53-A1
A36: Grupo: TARDE
A37: GII_4
A38: Hora | B38: LUNES | L38: MARTES | V38: MIÉRCOLES | AF38: JUEVES | AP38: VIERNES
A39: 14:30 - 15:30 | D39: (102) | E39: Lab. Automatica 2 | H39: (201) | I39: Lab 46-A1 | L39: (101) | M39: Aula 21-A1 | R39: (201) | S39: Lab. Automatica 2 | T39: (202) | U39: Lab 42-A1 | V39: (101) | W39: Lab 46-A1 | X39: (102) | Y39: Aula 21-A1 | AH39: (102) | AI39: Lab 46-A1 | AL39: (201) | AM39: Aula 21-A1 | AN39: (202) | AO39: Lab. Automatica 2 | AP39: (101) | AQ39: Lab. Automatica 2 | AR39: (102) | AS39: Lab 42-A1 | AV39: (201) | AW39: Lab 46-A1
D40: REDES | H40: HOMBRE-MAQ. | L40: ORGANIZACIÓN | R40: REDES | T40: HOMBRE-MAQ. | V40: HOMBRE-MAQ. | X40: ORGANIZACIÓN | AH40: SISTEMAS | AL40: ORGANIZACIÓN | AN40: REDES | AP40: REDES | AR40: HOMBRE-MAQ. | AV40: SISTEMAS
A41: 15:30 - 16:30
A43: 16:30 - 17:30 | B43: ORGANIZACIÓN | H43: Sala Juntas 2 | K43: 1 | L43: SISTEMAS | R43: Aula 53-A1 | U43: 1 | V43: HOMBRE-MAQ. | AB43: Aula 53-A1 | AE43: 1 | AP43: EST. DATOS | AV43: Aula 53-A1 | AY43: 1
B44: ORGANIZACIÓN | H44: Sala Juntas 2 | K44: 2 | L44: SISTEMAS | R44: Aula 53-A1 | U44: 2 | V44: HOMBRE-MAQ. | AB44: Aula 53-A1 | AE44: 2 | AF44: REDES | AL44: Aula 51-A1 | AO44: 2 | AP44: REDES | AV44: Aula 51-A1 | AY44: 2
A45: 17:30 - 18:30 | B45: ORGANIZACIÓN | H45: Sala Juntas 2 | K45: 1 | L45: HOMBRE-MAQ. | R45: Aula 53-A1 | U45: 1 | V45: SISTEMAS | AB45: Aula 53-A1 | AE45: 1 | AF45: REDES | AL45: Aula 53-A1 | AO45: 1 | AP45: REDES | AV45: Aula 53-A1 | AY45: 1
B46: ORGANIZACIÓN | H46: Sala Juntas 2 | K46: 2 | L46: HOMBRE-MAQ. | R46: Aula 53-A1 | U46: 2 | V46: SISTEMAS | AB46: Aula 53-A1 | AE46: 2 | AF46: EST. DATOS | AL46: Aula 51-A1 | AO46: 2 | AP46: EST. DATOS | AV46: Aula 51-A1 | AY46: 2
A47: 18:30 - 19:30 | B47: (101) | C47: Lab 46-A1 | R47: (201) | S47: Lab 46-A1 | X47: (102) | Y47: Lab 46-A1 | AF47: (101) | AG47: Lab 46-A1 | AN47: (202) | AO47: Lab 44-A1 | AP47: EST. DATOS | AT47: Aula 53-A1 | AW47: 1 | AX47: (202) | AY47: Lab 46-A1
B48: EST. DATOS | R48: EST. DATOS | X48: EST. DATOS | AF48: SISTEMAS | AN48: EST. DATOS | AX48: SISTEMAS
A49: 19:30 - 20:30
...

Sheet MINFORM
A1: =VLOOKUP(A4,ASIGNATURAS!$A$2:$D$151, 3, FALSE) -> 1º Máster en Ingeniería Informática | Z1: =Aulas!G5 -> Curso 2024-2025
A2: =VLOOKUP(A4,ASIGNATURAS!A2:D151, 2, FALSE) -> Semestre temporal: 1º (1º Semestre Académico) | Z2: Aula 32-A2
A3: Grupo: TARDE
A4: MINF_1
A5: Hora | B5: LUNES | H5: MARTES | N5: MIÉRCOLES | T5: JUEVES | Z5: VIERNES
A6: 15:30 - 16:30 | B6: GESTION TIC | H6: INT. ARTIFICIAL | N6: ARQ. Y SERV. INT. | T6: ARQ. AVANZADAS | Z6: SIST. INFORM.
B7: Aula 32-A2 | H7: Aula 32-A2 | N7: Aula 32-A2 | T7: Aula 32-A2 | Z7: Aula 32-A2
A8: 16:30 - 17:30 | B8: GESTION TIC | H8: ARQ. AVANZADAS | N8: ARQ. Y SERV. INT. | T8: INT. ARTIFICIAL | Z8: SIST. INFORM.
B9: Aula 32-A2 | H9: Aula 32-A2 | N9: Aula 32-A2 | T9: Aula 32-A2 | Z9: Aula 32-A2
A10: 17:30 - 18:30 | B10: SIST. INFORM. | H10: ARQ. AVANZADAS | N10: GESTION TIC | T10: INT. ARTIFICIAL
B11: Lab. 32-A1 | H11: Lab. 26-A1 | N11: Lab. 24-A1 | T11: Lab. 34-A1
A12: 18:30 - 19:30 | B12: SIST. INFORM. | H12: ARQ. AVANZADAS | N12: GESTION TIC | T12: INT. ARTIFICIAL
B13: Lab. 32-A1 | H13: Lab. 26-A1 | N13: Lab. 24-A1 | T13: Lab. 34-A1
A14: 19:30 - 20:30 | T14: ARQ. Y SERV. INT.
T15: Lab. 34-A1
A16: 20:30 - 21:30 | T16: ARQ. Y SERV. INT.
T17: Lab. 34-A1
A19: Nombre abreviado | C19: Nombre completo | M19: MII__1 | O19: ECTS | Q19: Profesor / es
A20: =VLOOKUP(M20,ASIGNATURAS!$F$1:$L$1022, 3, FALSE) -> #N/A | C20: =VLOOKUP(M20,ASIGNATURAS!$F$1:$L$1022, 4, FALSE) -> #N/A | M20: 7059 | O20: =VLOOKUP(M20,ASIGNATURAS!$F$1:$L$1022, 5, FALSE) -> #N/A | Q20: =VLOOKUP(M20,ASIGNATURAS!$F$1:$L$1022, 6, FALSE) -> #N/A
A21: =VLOOKUP(M21,ASIGNATURAS!$F$1:$L$1022, 3, FALSE) -> #N/A | C21: =VLOOKUP(M21,ASIGNATURAS!$F$1:$L$1022, 4, FALSE) -> #N/A | M21: 7060 | O21: =VLOOKUP(M21,ASIGNATURAS!$F$1:$L$1022, 5, FALSE) -> #N/A | Q21: =VLOOKUP(M21,ASIGNATURAS!$F$1:$L$1022, 6, FALSE) -> #N/A
A22: =VLOOKUP(M22,ASIGNATURAS!$F$1:$L$1022, 3, FALSE) -> #N/A | C22: =VLOOKUP(M22,ASIGNATURAS!$F$1:$L$1022, 4, FALSE) -> #N/A | M22: 7061 | O22: =VLOOKUP(M22,ASIGNATURAS!$F$1:$L$1022, 5, FALSE) -> #N/A | Q22: =VLOOKUP(M22,ASIGNATURAS!$F$1:$L$1022, 6, FALSE) -> #N/A
A23: =VLOOKUP(M23,ASIGNATURAS!$F$1:$L$1022, 3, FALSE) -> #N/A | C23: =VLOOKUP(M23,ASIGNATURAS!$F$1:$L$1022, 4, FALSE) -> #N/A | M23: 7062 | O23: =VLOOKUP(M23,ASIGNATURAS!$F$1:$L$1022, 5, FALSE) -> #N/A | Q23: =VLOOKUP(M23,ASIGNATURAS!$F$1:$L$1022, 6, FALSE) -> #N/A
A24: =VLOOKUP(M24,ASIGNATURAS!$F$1:$L$1022, 3, FALSE) -> #N/A | C24: =VLOOKUP(M24,ASIGNATURAS!$F$1:$L$1022, 4, FALSE) -> #N/A | M24: 7063 | O24: =VLOOKUP(M24,ASIGNATURAS!$F$1:$L$1022, 5, FALSE) -> #N/A | Q24: =VLOOKUP(M24,ASIGNATURAS!$F$1:$L$1022, 6, FALSE) -> #N/A
A27: GRUPOS TEORICOS = 1
A28: GRUPOS PRACTICOS = 1
A30: Nota: Estos horarios podrán ser modificados por necesidades docentes (desdoble de grupos, ocupación de laboratorios, contratación de profesorado…)
A32: =VLOOKUP(A35,ASIGNATURAS!$A$2:$D$151, 3, FALSE) -> 1º Máster en Ingeniería Informática | Z32: =Z1 -> Curso 2024-2025
A33: =VLOOKUP(A35,ASIGNATURAS!$A$2:$D$151, 2, FALSE) -> Semestre temporal: 2º (2º Semestre Académico) | Z33: Aula 32-A2
A34: Grupo: TARDE
A35: MINF_2
A36: Hora | B36: LUNES | H36: MARTES | N36: MIÉRCOLES | T36: JUEVES | Z36: VIERNES
A37: 15:30 - 16:30 | B37: DIRECCION PROY. | H37: INFORM. GRAF. | N37: INST. INF. | T37: AUDITORIA | Z37: INFORM. GRAF.
B38: Aula 32-A2 | H38: Aula 32-A2 | N38: Aula 32-A2 | T38: Aula 32-A2 | Z38: Lab. 34-A1
A39: 16:30 - 17:30 | B39: DIRECCION PROY. | H39: INFORM. GRAF. | N39: INST. INF. | T39: AUDITORIA | Z39: INFORM. GRAF.
B40: Aula 32-A2 | H40: Aula 32-A2 | N40: Aula 32-A2 | T40: Aula 32-A2 | Z40: Lab. 34-A1
A41: 17:30 - 18:30 | B41: INST. INF. | H41: DIRECCION PROY. | N41: AUDITORIA | T41: SIST. EMPOTRAD. | Z41: SIST. EMPOTRAD.
B42: Aula 32-A2 | H42: Lab. 22-A1 | N42: Lab. 32-A1 | T42: Lab. Automatica Aula 34-A1 | Z42: Aula 32-A2
A43: 18:30 - 19:30 | B43: INST. INF. | H43: DIRECCION PROY. | N43: AUDITORIA | T43: SIST. EMPOTRAD. | Z43: SIST. EMPOTRAD.
B44: Aula 32-A2 | H44: Lab. 22-A1 | N44: Lab. 32-A1 | T44: Lab. Automatica Aula 34-A1 | Z44: Aula 32-A2
A45: 19:30 - 20:30
...

Sheet MINDUST
A1: =VLOOKUP(A4,ASIGNATURAS!$A$2:$D$138, 3, FALSE) -> 1º Máster en Ingeniería Industrial | Z1: =Aulas!G5 -> Curso 2024-2025
A2: =VLOOKUP(A4,ASIGNATURAS!A2:D138, 2, FALSE) -> Semestre temporal: 1º (1º Semestre Académico) | Z2: Aula 31-A2
A3: Grupo: TARDE
A4: MIND_1
A5: Hora | B5: LUNES | H5: MARTES | N5: MIÉRCOLES | T5: JUEVES | Z5: VIERNES
A6: 14:30 - 15:30
A8: 15:30 - 16:30
A10: 16:30 - 17:30 | B10: TECN. ESTRUCT. | H10: GESTIÓN | N10: QUÍMICA IND. | T10: SIST. ELÉCTRIC. | Z10: DERECHO
B11: Lab. MMC | H11: Aula 31-A2 | N11: Aula 31-A2 | T11: Aula 31-A2 | Z11: Aula 31-A2
A12: 17:30 - 18:30 | B12: TECN. ESTRUCT. | H12: GESTIÓN | N12: QUÍMICA IND. | T12: SIST. ELÉCTRIC. | Z12: DERECHO
B13: Lab. MMC | H13: Aula 31-A2 | N13: Aula 31-A2 | T13: Aula 31-A2 | Z13: Aula 31-A2
A14: 18:30 - 19:30 | B14: GESTIÓN | H14: SIST. ELÉCTRIC. | N14: TECN. ESTRUCT. | T14: FABRIC. Y MAQ. | Z14: FABRIC. Y MAQ.
B15: Aula 31 A2/ Lab 22-A1 | H15: Aula 31-A2 | N15: Lab. MMC | T15: Aula 31A2 / Aula Inf1B | Z15: Aula 31A2 / Aula Inf1B
A16: 19:30 - 20:30 | B16: GESTIÓN | H16: SIST. ELÉCTRIC. | N16: TECN. ESTRUCT. | T16: FABRIC. Y MAQ. | Z16: FABRIC. Y MAQ.
B17: Aula 31 A2/ Lab 22-A1 | H17: Aula 31-A2 | N17: Lab. MMC | T17: Aula 31A2 / Aula Inf1B | Z17: Aula 31A2 / Aula Inf1B
A19: Nombre abreviado | C19: Nombre completo | M19: MIND__1 | O19: ECTS | Q19: Profesor / es
A20: =VLOOKUP(M20,ASIGNATURAS!$F$1:$L$1022, 3, FALSE) -> TECN. ESTRUCT. | C20: =VLOOKUP(M20,ASIGNATURAS!$F$1:$L$1022, 4, FALSE) -> Tecnología de Estructuras | M20: 7036 | O20: =VLOOKUP(M20,ASIGNATURAS!$F$1:$L$1022, 5, FALSE) -> 6 | Q20: =VLOOKUP(M20,ASIGNATURAS!$F$1:$L$1022, 6, FALSE) -> Luis Suarez Vivar, Wilco Verbeeten
A21: =VLOOKUP(M21,ASIGNATURAS!$F$1:$L$1022, 3, FALSE) -> GESTIÓN | C21: =VLOOKUP(M21,ASIGNATURAS!$F$1:$L$1022, 4, FALSE) -> Gestión de Empresas | M21: 7037 | O21: =VLOOKUP(M21,ASIGNATURAS!$F$1:$L$1022, 5, FALSE) -> 6 | Q21: =VLOOKUP(M21,ASIGNATURAS!$F$1:$L$1022, 6, FALSE) -> Juan José Lavios Villahoz
A22: =VLOOKUP(M22,ASIGNATURAS!$F$1:$L$1022, 3, FALSE) -> FABRIC. Y MAQ. | C22: =VLOOKUP(M22,ASIGNATURAS!$F$1:$L$1022, 4, FALSE) -> Fabricación y Máquinas | M22: 7038 | O22: =VLOOKUP(M22,ASIGNATURAS!$F$1:$L$1022, 5, FALSE) -> 6 | Q22: =VLOOKUP(M22,ASIGNATURAS!$F$1:$L$1022, 6, FALSE) -> Francisco Javier Gómez Gil
A23: =VLOOKUP(M23,ASIGNATURAS!$F$1:$L$1022, 3, FALSE) -> SIST. ELÉCTRIC. | C23: =VLOOKUP(M23,ASIGNATURAS!$F$1:$L$1022, 4, FALSE) -> Sistemas Eléctricos de Potencia | M23: 7039 | O23: =VLOOKUP(M23,ASIGNATURAS!$F$1:$L$1022, 5, FALSE) -> 6 | Q23: =VLOOKUP(M23,ASIGNATURAS!$F$1:$L$1022, 6, FALSE) -> Jesús Sagredo González
A24: =VLOOKUP(M24,ASIGNATURAS!$F$1:$L$1022, 3, FALSE) -> DERECHO | C24: =VLOOKUP(M24,ASIGNATURAS!$F$1:$L$1022, 4, FALSE) -> Derecho Mercantil y Laboral | M24: 7040 | O24: =VLOOKUP(M24,ASIGNATURAS!$F$1:$L$1022, 5, FALSE) -> 3 | Q24: =VLOOKUP(M24,ASIGNATURAS!$F$1:$L$1022, 6, FALSE) -> Juan Cruz Monje Santillana
A25: =VLOOKUP(M25,ASIGNATURAS!$F$1:$L$1022, 3, FALSE) -> QUÍMICA IND. | C25: =VLOOKUP(M25,ASIGNATURAS!$F$1:$L$1022, 4, FALSE) -> Química Industrial | M25: 7041 | O25: =VLOOKUP(M25,ASIGNATURAS!$F$1:$L$1022, 5, FALSE) -> 3 | Q25: =VLOOKUP(M25,ASIGNATURAS!$F$1:$L$1022, 6, FALSE) -> Fco. Javier Rodríguez Vidal, Luis Marcos Naveira
A28: GRUPOS TEÓRICOS = 1
A29: GRUPOS PRÁCTICOS = 1
A31: Nota: Estos horarios podrán ser modificados por necesidades docentes (desdoble de grupos, ocupación de laboratorios, contratación de profesorado…)
A33: =VLOOKUP(A36,ASIGNATURAS!$A$2:$D$138, 3, FALSE) -> 1º Máster en Ingeniería Industrial | Z33: =Z1 -> Curso 2024-2025
A34: =VLOOKUP(A36,ASIGNATURAS!$A$2:$D$138, 2, FALSE) -> Semestre temporal: 2º (2º Semestre Académico) | Z34: Aula 33-A2
A35: Grupo: TARDE
A36: MIND_2
A37: Hora | B37: LUNES | H37: MARTES | N37: MIÉRCOLES | T37: JUEVES | Z37: VIERNES
A38: 14:30 - 15:30
A40: 15:30 - 16:30
A42: 16:30 - 17:30 | B42: CONST. Y EDIFIC. | H42: ING. ENERGÉTICA | N42: DIRECCIÓN PROD. | T42: DIRECCIÓN PROD. | Z42: ING. ELECTRÓN.
B43: Aula 33-A2 | H43: Aula 33-A2 | N43: Aula 33A2 / Aula Inf 2B | T43: Aula Inf. 2 B | Z43: Aula 33-A2
A44: 17:30 - 18:30 | B44: CONST. Y EDIFIC. | H44: ING. ENERGÉTICA | N44: DIRECCIÓN PROD. | T44: DIRECCIÓN PROD. | Z44: ING. ELECTRÓN.
B45: Aula 33-A2 | H45: Aula 33-A2 | N45: Aula 33A2 / Aula Inf 2B | T45: Aula Inf. 2 B | Z45: Aula 33-A2
A46: 18:30 - 19:30 | B46: ING. ENERGÉTICA | H46: CONST. Y EDIFIC. | N46: ING. ELECTRÓN. | T46: CONT. PROCESOS | Z46: CONT. PROCESOS
B47: Lab. Ing. Energetica 1/Aula 33 A2 | H47: Aula 33-A2 | N47: Lab. Electrónica 1 | T47: Lab. Automatica 2 | Z47: Lab. Automatica 2
A48: 19:30 - 20:30 | B48: ING. ENERGÉTICA | H48: CONST. Y EDIFIC. | N48: ING. ELECTRÓN. | T48: CONT. PROCESOS | Z48: CONT. PROCESOS
B49: Lab. Ing. Energetica 1/Aula 33 A2 | H49: Aula 33-A2 | N49: Lab. Electrónica 1 | T49: Lab. Automatica 2 | Z49: Lab. Automatica 2
...

Sheet MDURAB
A1: =VLOOKUP(A4,ASIGNATURAS!$A$2:$D$151, 3, FALSE) -> Máster en Integridad y Durabilidad de Materiales | Z1: =Aulas!G5 -> Curso 2024-2025
A2: =VLOOKUP(A4,ASIGNATURAS!A2:D151, 2, FALSE) -> Semestre temporal: 1º (1º Semestre Académico)
A3: Grupo: TARDE
A4: MDURAB_1
A5: Hora | B5: LUNES | H5: MARTES | N5: MIÉRCOLES | T5: JUEVES | Z5: VIERNES
A6: 16:00 - 17:00
A8: 17:00 - 18:00 | B8: FRACTURA | H8: ELAST-PLAS | N8: SOLDADURA | T8: FATIGA
B9: Laboratorio MMC | H9: Aula 4114 | N9: Lab. Materiales | T9: Aula 4114
A10: 18:00 - 19:00 | B10: FRACTURA | H10: ELAST-PLAS | N10: SOLDADURA | T10: FATIGA
B11: Aula 4114 | H11: Aula 4114 | N11: Aula 4114 | T11: Aula 4114
A12: 19:00 - 20:00 | B12: MATERIALES | H12: SIMULACION NUMERICA | N12: CORROSION
B13: Aula 4114 | H13: Aula 4114 | N13: Aula 4114
A14: 20:00 - 21:00 | B14: MATERIALES | H14: SIMULACION NUMERICA | N14: CORROSION
B15: Lab. Materiales | H15: Laboratorio MMC | N15: Lab. Materiales
A17: Nombre abreviado | C17: Nombre completo | M17: MDUR__1 | O17: ECTS | Q17: Profesor / es
A18: =VLOOKUP(M18,ASIGNATURAS!$F$1:$L$1022, 3, FALSE) -> MATERIALES | C18: =VLOOKUP(M18,ASIGNATURAS!$F$1:$L$1022, 4, FALSE) -> Materiales Estructurales | M18: 7101 | O18: =VLOOKUP(M18,ASIGNATURAS!$F$1:$L$1022, 5, FALSE) -> 4 | Q18: =VLOOKUP(M18,ASIGNATURAS!$F$1:$L$1022, 6, FALSE) -> Fco. Javier Belzunce (UNIOVI), Monica Preciado (UBU)
A19: =VLOOKUP(M19,ASIGNATURAS!$F$1:$L$1022, 3, FALSE) -> ELAST-PLAS | C19: =VLOOKUP(M19,ASIGNATURAS!$F$1:$L$1022, 4, FALSE) -> Teoría de la Elasticidad y Plasticidad | M19: 7102 | O19: =VLOOKUP(M19,ASIGNATURAS!$F$1:$L$1022, 5, FALSE) -> 4 | Q19: =VLOOKUP(M19,ASIGNATURAS!$F$1:$L$1022, 6, FALSE) -> Wilco Verbeeten (UBU)
A20: =VLOOKUP(M20,ASIGNATURAS!$F$1:$L$1022, 3, FALSE) -> FRACTURA | C20: =VLOOKUP(M20,ASIGNATURAS!$F$1:$L$1022, 4, FALSE) -> Mecánica de la Fractura | M20: 7103 | O20: =VLOOKUP(M20,ASIGNATURAS!$F$1:$L$1022, 5, FALSE) -> 4 | Q20: =VLOOKUP(M20,ASIGNATURAS!$F$1:$L$1022, 6, FALSE) -> Covadonga Betegón Biempica (UNIOVI), Ivan Cuesta Segura (UBU)
A21: =VLOOKUP(M21,ASIGNATURAS!$F$1:$L$1022, 3, FALSE) -> FATIGA | C21: =VLOOKUP(M21,ASIGNATURAS!$F$1:$L$1022, 4, FALSE) -> Fatiga, Corrosión Bajo Tensión y Fluencia | M21: 7104 | O21: =VLOOKUP(M21,ASIGNATURAS!$F$1:$L$1022, 5, FALSE) -> 4 | Q21: =VLOOKUP(M21,ASIGNATURAS!$F$1:$L$1022, 6, FALSE) -> Jose Alberto Alvarez (UNICAN), Jesús Manuel Alegre (UBU)
A22: =VLOOKUP(M22,ASIGNATURAS!$F$1:$L$1022, 3, FALSE) -> CORROSIÓN | C22: =VLOOKUP(M22,ASIGNATURAS!$F$1:$L$1022, 4, FALSE) -> Corrosión, Oxidación, Desgaste y Protección | M22: 7105 | O22: =VLOOKUP(M22,ASIGNATURAS!$F$1:$L$1022, 5, FALSE) -> 4 | Q22: =VLOOKUP(M22,ASIGNATURAS!$F$1:$L$1022, 6, FALSE) -> Pedro Bravo Diez (UBU)
A23: =VLOOKUP(M23,ASIGNATURAS!$F$1:$L$1022, 3, FALSE) -> SOLDADURA | C23: =VLOOKUP(M23,ASIGNATURAS!$F$1:$L$1022, 4, FALSE) -> Soldadura y Tecnologías de Unión | M23: 7108 | O23: =VLOOKUP(M23,ASIGNATURAS!$F$1:$L$1022, 5, FALSE) -> 4 | Q23: =VLOOKUP(M23,ASIGNATURAS!$F$1:$L$1022, 6, FALSE) -> Cristina Rodriguez (UNIOVI), Monica Preciado (UBU)
A24: =VLOOKUP(M24,ASIGNATURAS!$F$1:$L$1022, 3, FALSE) -> SIMULACIÓN NÚMERICA | C24: =VLOOKUP(M24,ASIGNATURAS!$F$1:$L$1022, 4, FALSE) -> Simulación Numérica de Mat, Comp y Est. | M24: 7106 | O24: =VLOOKUP(M24,ASIGNATURAS!$F$1:$L$1022, 5, FALSE) -> 4 | Q24: =VLOOKUP(M24,ASIGNATURAS!$F$1:$L$1022, 6, FALSE) -> Ivan Cuesta Segura (UBU)
A27: GRUPOS TEÓRICOS = 1
A28: GRUPOS PRÁCTICOS = 1
A30: Nota: Estos horarios podrán ser modificados por necesidades docentes (desdoble de grupos, ocupación de laboratorios, contratación de profesorado…)
A32: =VLOOKUP(A35,ASIGNATURAS!$A$2:$D$151, 3, FALSE) -> Máster en Integridad y Durabilidad de Materiales | Z32: =Z1 -> Curso 2024-2025
A33: =VLOOKUP(A35,ASIGNATURAS!$A$2:$D$151, 2, FALSE) -> Semestre temporal: 2º (2º Semestre Académico)
A34: Grupo: TARDE
A35: MDURAB_2
A36: Hora | B36: LUNES | H36: MARTES | N36: MIÉRCOLES | T36: JUEVES | Z36: VIERNES
A37: 16:00 - 17:00
A39: 17:00 - 18:00 | B39: INTEGRIDAD ESTRUCTURAL | H39: SEMINARIO I | N39: ANÁLISIS DE FALLOS | T39: INSPECCIÓN Y END
B40: Lab. MMC | H40: Lab. MMC | N40: Lab. Materiales | T40: Lab. Materiales
A41: 18:00 - 19:00 | B41: INTEGRIDAD ESTRUCTURAL | H41: SEMINARIO I | N41: ANÁLISIS DE FALLOS | T41: INSPECCIÓN Y END
B42: Aula 4114 | H42: Lab. MMC | N42: Aula 4114 | T42: Aula 4114
A43: 19:00 - 20:00 | B43: INTEGRIDAD ESTRUCTURAL | H43: SEMINARIO I | N43: ANÁLISIS DE FALLOS | T43: INSPECCIÓN Y END
B44: Aula 4114 | H44: Lab. MMC | N44: Aula 4114 | T44: Aula 4114
A45: 20:00 - 21:00 | B45: INTEGRIDAD ESTRUCTURAL | H45: SEMINARIO I | N45: ANÁLISIS DE FALLOS | T45: INSPECCIÓN Y END
B46: Lab. MMC | H46: Lab. MMC | N46: Lab. Materiales | T46: Lab. Materiales
A48: Nombre abreviado | C48: Nombre completo | M48: MDUR__2 | O48: ECTS | Q48: Profesor / es
...

Sheet MESO
A1: MASTER DE PROFESORADO EN EDUCACIÓN | Z1: =Aulas!G5 -> Curso 2024-2025
A2: Semestre temporal: 1º (1º Semestre Académico) | Z2: Aula 42-A2
A3: Grupo: TARDE
A4: MESO 1
A5: Hora | B5: LUNES | H5: MARTES | N5: MIÉRCOLES | T5: JUEVES | Z5: VIERNES
A6: 15:30 - 16:30 | N6: T. Industriales | T6: T. Industriales
N7: Aula 42-A2 | T7: Aula 42-A2
A8: 16:30 - 17:30 | N8: T. Industriales | T8: T. Industriales
N9: T. información | T9: T. información
A10: 17:30 - 18:30 | N10: T. información | T10: TICRobótica
N11: Lab. 22-A1 | T11: Lab. 22-A1
A12: 18:30 - 19:30 | N12: TICRobótica | T12: TICRobótica
N13: Lab. 22-A1 | T13: Lab. 22-A1
A14: 19:30 - 20:30
A16: 20:30 - 21:30
A19: Nombre abreviado | C19: Nombre completo | M19: MIND__1 | O19: ECTS | Q19: Profesor / es
A20: =VLOOKUP(M20,ASIGNATURAS!$F$1:$L$1022, 3, FALSE) -> TECN. ESTRUCT. | C20: =VLOOKUP(M20,ASIGNATURAS!$F$1:$L$1022, 4, FALSE) -> Tecnología de Estructuras | M20: 7036 | O20: =VLOOKUP(M20,ASIGNATURAS!$F$1:$L$1022, 5, FALSE) -> 6 | Q20: =VLOOKUP(M20,ASIGNATURAS!$F$1:$L$1022, 6, FALSE) -> Luis Suarez Vivar, Wilco Verbeeten
A21: =VLOOKUP(M21,ASIGNATURAS!$F$1:$L$1022, 3, FALSE) -> GESTIÓN | C21: =VLOOKUP(M21,ASIGNATURAS!$F$1:$L$1022, 4, FALSE) -> Gestión de Empresas | M21: 7037 | O21: =VLOOKUP(M21,ASIGNATURAS!$F$1:$L$1022, 5, FALSE) -> 6 | Q21: =VLOOKUP(M21,ASIGNATURAS!$F$1:$L$1022, 6, FALSE) -> Juan José Lavios Villahoz
A22: =VLOOKUP(M22,ASIGNATURAS!$F$1:$L$1022, 3, FALSE) -> FABRIC. Y MAQ. | C22: =VLOOKUP(M22,ASIGNATURAS!$F$1:$L$1022, 4, FALSE) -> Fabricación y Máquinas | M22: 7038 | O22: =VLOOKUP(M22,ASIGNATURAS!$F$1:$L$1022, 5, FALSE) -> 6 | Q22: =VLOOKUP(M22,ASIGNATURAS!$F$1:$L$1022, 6, FALSE) -> Francisco Javier Gómez Gil
A23: =VLOOKUP(M23,ASIGNATURAS!$F$1:$L$1022, 3, FALSE) -> SIST. ELÉCTRIC. | C23: =VLOOKUP(M23,ASIGNATURAS!$F$1:$L$1022, 4, FALSE) -> Sistemas Eléctricos de Potencia | M23: 7039 | O23: =VLOOKUP(M23,ASIGNATURAS!$F$1:$L$1022, 5, FALSE) -> 6 | Q23: =VLOOKUP(M23,ASIGNATURAS!$F$1:$L$1022, 6, FALSE) -> Jesús Sagredo González
A24: =VLOOKUP(M24,ASIGNATURAS!$F$1:$L$1022, 3, FALSE) -> DERECHO | C24: =VLOOKUP(M24,ASIGNATURAS!$F$1:$L$1022, 4, FALSE) -> Derecho Mercantil y Laboral | M24: 7040 | O24: =VLOOKUP(M24,ASIGNATURAS!$F$1:$L$1022, 5, FALSE) -> 3 | Q24: =VLOOKUP(M24,ASIGNATURAS!$F$1:$L$1022, 6, FALSE) -> Juan Cruz Monje Santillana
A25: =VLOOKUP(M25,ASIGNATURAS!$F$1:$L$1022, 3, FALSE) -> QUÍMICA IND. | C25: =VLOOKUP(M25,ASIGNATURAS!$F$1:$L$1022, 4, FALSE) -> Química Industrial | M25: 7041 | O25: =VLOOKUP(M25,ASIGNATURAS!$F$1:$L$1022, 5, FALSE) -> 3 | Q25: =VLOOKUP(M25,ASIGNATURAS!$F$1:$L$1022, 6, FALSE) -> Fco. Javier Rodríguez Vidal, Luis Marcos Naveira
A28: GRUPOS TEÓRICOS = 1
A29: GRUPOS PRÁCTICOS = 1
A31: Nota: Estos horarios podrán ser modificados por necesidades docentes (desdoble de grupos, ocupación de laboratorios, contratación de profesorado…)
A33: =A1 -> MASTER DE PROFESORADO EN EDUCACIÓN | Z33: =Z1 -> Curso 2024-2025
A34: Semestre temporal: 2º (2º Semestre Académico) | Z34: Lab. 24-A1
A35: Grupo: TARDE
A36: MESO 2
A37: Hora | B37: LUNES | H37: MARTES | N37: MIÉRCOLES | T37: JUEVES | Z37: VIERNES
A38: 15:30 - 16:30 | B38: Estructura y gestión de la formación profesional | H38: Aprendizaje basado en proyectos | N38: Estructura y gestión de la formación profesional | T38: Aprendizaje basado en proyectos
B39: Lab. 24-A1 | H39: Lab. 24-A1 | N39: Lab. 24-A1 | T39: Lab. 24-A1
A40: 16:30 - 17:30 | B40: Estructura y gestión de la formación profesional | H40: Aprendizaje basado en proyectos | N40: Estructura y gestión de la formación profesional | T40: Aprendizaje basado en proyectos
B41: Lab. 24-A1 | H41: Lab. 24-A1 | N41: Lab. 24-A1 | T41: Lab. 24-A1
A42: 17:30 - 18:30 | B42: Aprendizaje basado en proyectos | H42: Innovación docente e iniciación a la investigación educativa en tecnología | N42: Innovación docente e iniciación a la investigación educativa en tecnología | T42: Estructura y gestión de la formación profesional
B43: Lab. 24-A1 | H43: Lab. 24-A1 | N43: Lab. 24-A1 | T43: Lab. 24-A1
A44: 18:30 - 19:30 | B44: Aprendizaje basado en proyectos | H44: Innovación docente e iniciación a la investigación educativa en tecnología | N44: Innovación docente e iniciación a la investigación educativa en tecnología | T44: Estructura y gestión de la formación profesional
B45: Lab. 24-A1 | H45: Lab. 24-A1 | N45: Lab. 24-A1 | T45: Lab. 24-A1
A46: 19:30 - 20:30
A48: 20:30 - 21:30
...

Sheet ASIGNATURAS
F1: GRADO EN INGENIERIA MECANICA
A2: GIM_1 | B2: Semestre temporal: 1º (1º Semestre Académico) | C2: 1º Grado en Ingeniería Mecánica | D2: GIM__1 | F2: CODIGO | G2: SEMESTRE | H2: NOMBRE CORTO | I2: NOMBRE COMPLETO | J2: ECTS | K2: PROFESORES | L2: PROFESOR 1 | N2: PROFESOR 2 | P2: PROFESOR 3 | R2: PROFESOR 4 | T2: PROFESOR 5
A3: GIM_2 | B3: Semestre temporal: 2º (2º Semestre Académico) | C3: 1º Grado en Ingeniería Mecánica | D3: GIM__2 | F3: 6302 | G3: 1 | H3: CALCULO | I3: Cálculo | J3: 6 | K3: =CONCATENATE(L3,M3,N3,O3,P3,Q3,R3) -> Ana García | L3: Ana García | M3: =IF(N3<>"",", ","") | O3: =IF(P3<>"",", ","") | Q3: =IF(R3<>"",", ","") | S3: =IF(T3<>"",", ","")
A4: GIM_3 | B4: Semestre temporal: 1º (3º Semestre Académico) | C4: 2º Grado en Ingeniería Mecánica | D4: GIM__3 | F4: 6304 | G4: 1 | H4: FISICA I | I4: Física I | J4: 6 | K4: =CONCATENATE(L4,M4,N4,O4,P4,Q4,R4) -> Juan José Villalaín, Alfonso Blasco, María del Mar Chichón | L4: Juan José Villalaín | M4: =IF(N4<>"",", ","") -> , | N4: Alfonso Blasco | O4: =IF(P4<>"",", ","") -> , | P4: María del Mar Chichón | Q4: =IF(R4<>"",", ","") | S4: =IF(T4<>"",", ","")
A5: GIM_4 | B5: Semestre temporal: 2º (4º Semestre Académico) | C5: 2º Grado en Ingeniería Mecánica | D5: GIM__4 | F5: 6303 | G5: 1 | H5: ALGEBRA | I5: Álgebra y Ecuaciones Diferenciales | J5: 6 | K5: =CONCATENATE(L5,M5,N5,O5,P5,Q5,R5) -> José Javier Relancio | L5: José Javier Relancio | M5: =IF(N5<>"",", ","") | O5: =IF(P5<>"",", ","") | Q5: =IF(R5<>"",", ","") | S5: =IF(T5<>"",", ","")
A6: GIM_5 | B6: Semestre temporal: 1º (5º Semestre Académico) | C6: 3º Grado en Ingeniería Mecánica | D6: GIM__5 | F6: 6306 | G6: 1 | H6: EXP. GRAFICA I | I6: Expresión Gráfica I | J6: 6 | K6: =CONCATENATE(L6,M6,N6,O6,P6,Q6,R6) -> Arturo de Román , Elías Martínez | L6: Arturo de Román | M6: =IF(N6<>"",", ","") -> , | N6: Elías Martínez | O6: =IF(P6<>"",", ","") | Q6: =IF(R6<>"",", ","") | S6: =IF(T6<>"",", ","")
A7: GIM_6 | B7: Semestre temporal: 2º (6º Semestre Académico) | C7: 3º Grado en Ingeniería Mecánica | D7: GIM__6 | F7: 6305 | G7: 1 | H7: QUIMICA | I7: Química | J7: 6 | K7: =CONCATENATE(L7,M7,N7,O7,P7,Q7,R7) -> Fco. Javier Rodríguez | L7: Fco. Javier Rodríguez | M7: =IF(N7<>"",", ","") | O7: =IF(P7<>"",", ","") | Q7: =IF(R7<>"",", ","") | S7: =IF(T7<>"",", ","") | U7: 1
A8: GIM_7 | B8: Semestre temporal: 1º (7º Semestre Académico) | C8: 4º Grado en Ingeniería Mecánica | D8: GIM__7 | G8: 1 | H8: EXPRESION GRAFICA | K8: =CONCATENATE(L8,M8,N8,O8,P8,Q8,R8) | M8: =IF(N8<>"",", ","") | O8: =IF(P8<>"",", ","") | Q8: =IF(R8<>"",", ","") | S8: =IF(T8<>"",", ","") | U8: 2
A9: GIM_8 | B9: Semestre temporal: 2º (8º Semestre Académico) | C9: 4º Grado en Ingeniería Mecánica | D9: GIM__8 | F9: 6307 | G9: 2 | H9: AMP. CALCULO | I9: Ampliación de Cálculo y Geometría | J9: 6 | K9: =CONCATENATE(L9,M9,N9,O9,P9,Q9,R9) -> Iván Gutiérrez | L9: Iván Gutiérrez | M9: =IF(N9<>"",", ","") | O9: =IF(P9<>"",", ","") | Q9: =IF(R9<>"",", ","") | S9: =IF(T9<>"",", ","")
F10: 6309 | G10: 2 | H10: FISICA II | I10: Física II | J10: 6 | K10: =CONCATENATE(L10,M10,N10,O10,P10,Q10,R10) -> Mª Isabel Blanco, Mª Felicidad Bógalo, Manuel Iván González | L10: Mª Isabel Blanco | M10: =IF(N11<>"",", ","") -> , | N10: Mª Felicidad Bógalo | O10: =IF(P10<>"",", ","") -> , | P10: Manuel Iván González | Q10: =IF(R10<>"",", ","") | S10: =IF(T10<>"",", ","")
A11: GIE_1 | B11: Semestre temporal: 1º (1º Semestre Académico) | C11: 1º Grado en Ingeniería Electrónica Industrial y Automática | D11: GIE__1 | F11: 6308 | G11: 2 | H11: INFORMATICA | I11: Informática Básica | J11: 6 | K11: =CONCATENATE(L11,M11,N11,O11,P11,Q11,R11) -> Beatriz Gil, Belen Vaquerizo | L11: Beatriz Gil | M11: =IF(N12<>"",", ","") -> , | N11: Belen Vaquerizo | O11: =IF(P11<>"",", ","") | Q11: =IF(R11<>"",", ","") | S11: =IF(T11<>"",", ","")
A12: GIE_2 | B12: Semestre temporal: 2º (2º Semestre Académico) | C12: 1º Grado en Ingeniería Electrónica Industrial y Automática | D12: GIE__2 | F12: 6311 | G12: 2 | H12: ECONOMIA | I12: Economía de la Empresa | J12: 6 | K12: =CONCATENATE(L12,M12,N12,O12,P12,Q12,R12) -> Juan Mª Espinosa, Rosario González | L12: Juan Mª Espinosa | M12: =IF(N12<>"",", ","") -> , | N12: Rosario González | O12: =IF(P12<>"",", ","") | Q12: =IF(R12<>"",", ","") | S12: =IF(T12<>"",", ","")
A13: GIE_3 | B13: Semestre temporal: 1º (3º Semestre Académico) | C13: 2º Grado en Ingeniería Electrónica Industrial y Automática | D13: GIE__3 | F13: 6310 | G13: 2 | H13: MATERIALES | I13: Ciencia de Materiales: Est. y propiedades | J13: 6 | K13: =CONCATENATE(L13,M13,N13,O13,P13,Q13,R13) -> José Calaf Chica, David Cárdenas | L13: José Calaf Chica | M13: =IF(N13<>"",", ","") -> , | N13: David Cárdenas | O13: =IF(P13<>"",", ","") | Q13: =IF(R13<>"",", ","") | S13: =IF(T13<>"",", ","")
A14: GIE_4 | B14: Semestre temporal: 2º (4º Semestre Académico) | C14: 2º Grado en Ingeniería Electrónica Industrial y Automática | D14: GIE__4 | F14: 6312 | G14: 3 | H14: TERMICA I | I14: Ingeniería Térmica I | J14: 6 | K14: =CONCATENATE(L14,M14,N14,O14,P14,Q14,R14) -> David González | L14: David González | M14: =IF(N14<>"",", ","") | O14: =IF(P14<>"",", ","") | Q14: =IF(N14<>"",", ","") | S14: =IF(P14<>"",", ","")
A15: GIE_5 | B15: Semestre temporal: 1º (5º Semestre Académico) | C15: 3º Grado en Ingeniería Electrónica Industrial y Automática | D15: GIE__5 | F15: 6313 | G15: 3 | H15: ING. ELECTRICA | I15: Fundamentos de Ingeniería Eléctrica | J15: 6 | K15: =CONCATENATE(L15,M15,N15,O15,P15,Q15,R15) -> Victoria Abad San Martín | L15: Victoria Abad San Martín | M15: =IF(N15<>"",", ","") | O15: =IF(P15<>"",", ","") | Q15: =IF(R15<>"",", ","") | S15: =IF(T15<>"",", ","")
A16: GIE_6 | B16: Semestre temporal: 2º (6º Semestre Académico) | C16: 3º Grado en Ingeniería Electrónica Industrial y Automática | D16: GIE__6 | F16: 6314 | G16: 3 | H16: ERMAT I | I16: Elasticidad y Resistencia de Materiales | J16: 6 | K16: =CONCATENATE(L16,M16,N16,O16,P16,Q16,R16) -> Isidoro Iván Cuesta | L16: Isidoro Iván Cuesta | M16: =IF(N16<>"",", ","") | O16: =IF(P16<>"",", ","") | Q16: =IF(R16<>"",", ","") | S16: =IF(T16<>"",", ","")
